[2025-04-01T10:05:35.766+0000] {taskinstance.py:1159} INFO - Dependencies all met for dep_context=non-requeueable deps ti=<TaskInstance: etl_pipeline.transform manual__2025-04-01T09:45:00+00:00 [queued]>
[2025-04-01T10:05:35.771+0000] {taskinstance.py:1159} INFO - Dependencies all met for dep_context=requeueable deps ti=<TaskInstance: etl_pipeline.transform manual__2025-04-01T09:45:00+00:00 [queued]>
[2025-04-01T10:05:35.771+0000] {taskinstance.py:1361} INFO - Starting attempt 2 of 2
[2025-04-01T10:05:35.778+0000] {taskinstance.py:1382} INFO - Executing <Task(PythonOperator): transform> on 2025-04-01 09:45:00+00:00
[2025-04-01T10:05:35.782+0000] {standard_task_runner.py:57} INFO - Started process 180 to run task
[2025-04-01T10:05:35.784+0000] {standard_task_runner.py:84} INFO - Running: ['airflow', 'tasks', 'run', 'etl_pipeline', 'transform', 'manual__2025-04-01T09:45:00+00:00', '--job-id', '208', '--raw', '--subdir', 'DAGS_FOLDER/etl_dags.py', '--cfg-path', '/tmp/tmp8gk18qiq']
[2025-04-01T10:05:35.785+0000] {standard_task_runner.py:85} INFO - Job 208: Subtask transform
[2025-04-01T10:05:35.795+0000] {logging_mixin.py:154} WARNING - /home/airflow/.local/lib/python3.8/site-packages/airflow/settings.py:195 DeprecationWarning: The sql_alchemy_conn option in [core] has been moved to the sql_alchemy_conn option in [database] - the old setting has been used, but please update your config.
[2025-04-01T10:05:35.818+0000] {task_command.py:416} INFO - Running <TaskInstance: etl_pipeline.transform manual__2025-04-01T09:45:00+00:00 [running]> on host d6317adea708
[2025-04-01T10:05:35.867+0000] {taskinstance.py:1662} INFO - Exporting env vars: AIRFLOW_CTX_DAG_OWNER='airflow' AIRFLOW_CTX_DAG_ID='etl_pipeline' AIRFLOW_CTX_TASK_ID='transform' AIRFLOW_CTX_EXECUTION_DATE='2025-04-01T09:45:00+00:00' AIRFLOW_CTX_TRY_NUMBER='2' AIRFLOW_CTX_DAG_RUN_ID='manual__2025-04-01T09:45:00+00:00'
[2025-04-01T10:05:35.877+0000] {taskinstance.py:1937} ERROR - Task failed with exception
Traceback (most recent call last):
  File "/home/airflow/.local/lib/python3.8/site-packages/airflow/operators/python.py", line 192, in execute
    return_value = self.execute_callable()
  File "/home/airflow/.local/lib/python3.8/site-packages/airflow/operators/python.py", line 209, in execute_callable
    return self.python_callable(*self.op_args, **self.op_kwargs)
  File "/opt/airflow/dags/scripts/transform.py", line 162, in transform_data
    df_aqi_traffic = pd.merge(df_aqi, df_traffic, on="district", how="inner")
  File "/home/airflow/.local/lib/python3.8/site-packages/pandas/core/reshape/merge.py", line 148, in merge
    op = _MergeOperation(
  File "/home/airflow/.local/lib/python3.8/site-packages/pandas/core/reshape/merge.py", line 737, in __init__
    ) = self._get_merge_keys()
  File "/home/airflow/.local/lib/python3.8/site-packages/pandas/core/reshape/merge.py", line 1203, in _get_merge_keys
    right_keys.append(right._get_label_or_level_values(rk))
  File "/home/airflow/.local/lib/python3.8/site-packages/pandas/core/generic.py", line 1778, in _get_label_or_level_values
    raise KeyError(key)
KeyError: 'district'
[2025-04-01T10:05:35.890+0000] {taskinstance.py:1400} INFO - Marking task as FAILED. dag_id=etl_pipeline, task_id=transform, execution_date=20250401T094500, start_date=20250401T100535, end_date=20250401T100535
[2025-04-01T10:05:35.897+0000] {standard_task_runner.py:104} ERROR - Failed to execute job 208 for task transform ('district'; 180)
[2025-04-01T10:05:35.917+0000] {local_task_job_runner.py:228} INFO - Task exited with return code 1
[2025-04-01T10:05:35.932+0000] {taskinstance.py:2778} INFO - 0 downstream tasks scheduled from follow-on schedule check
