[2025-04-01T09:22:26.229+0000] {taskinstance.py:1159} INFO - Dependencies all met for dep_context=non-requeueable deps ti=<TaskInstance: etl_pipeline.extract scheduled__2025-04-01T07:45:00+00:00 [queued]>
[2025-04-01T09:22:26.235+0000] {taskinstance.py:1159} INFO - Dependencies all met for dep_context=requeueable deps ti=<TaskInstance: etl_pipeline.extract scheduled__2025-04-01T07:45:00+00:00 [queued]>
[2025-04-01T09:22:26.235+0000] {taskinstance.py:1361} INFO - Starting attempt 1 of 2
[2025-04-01T09:22:26.244+0000] {taskinstance.py:1382} INFO - Executing <Task(PythonOperator): extract> on 2025-04-01 07:45:00+00:00
[2025-04-01T09:22:26.247+0000] {standard_task_runner.py:57} INFO - Started process 71 to run task
[2025-04-01T09:22:26.249+0000] {standard_task_runner.py:84} INFO - Running: ['airflow', 'tasks', 'run', 'etl_pipeline', 'extract', 'scheduled__2025-04-01T07:45:00+00:00', '--job-id', '200', '--raw', '--subdir', 'DAGS_FOLDER/etl_dags.py', '--cfg-path', '/tmp/tmpxt9pygln']
[2025-04-01T09:22:26.251+0000] {standard_task_runner.py:85} INFO - Job 200: Subtask extract
[2025-04-01T09:22:26.262+0000] {logging_mixin.py:154} WARNING - /home/airflow/.local/lib/python3.8/site-packages/airflow/settings.py:195 DeprecationWarning: The sql_alchemy_conn option in [core] has been moved to the sql_alchemy_conn option in [database] - the old setting has been used, but please update your config.
[2025-04-01T09:22:26.287+0000] {task_command.py:416} INFO - Running <TaskInstance: etl_pipeline.extract scheduled__2025-04-01T07:45:00+00:00 [running]> on host ac1e9720efb0
[2025-04-01T09:22:26.346+0000] {taskinstance.py:1662} INFO - Exporting env vars: AIRFLOW_CTX_DAG_OWNER='airflow' AIRFLOW_CTX_DAG_ID='etl_pipeline' AIRFLOW_CTX_TASK_ID='extract' AIRFLOW_CTX_EXECUTION_DATE='2025-04-01T07:45:00+00:00' AIRFLOW_CTX_TRY_NUMBER='1' AIRFLOW_CTX_DAG_RUN_ID='scheduled__2025-04-01T07:45:00+00:00'
[2025-04-01T09:24:28.398+0000] {logging_mixin.py:154} INFO - ðŸŒŸ Extract city list completely
[2025-04-01T09:24:28.400+0000] {taskinstance.py:1937} ERROR - Task failed with exception
Traceback (most recent call last):
  File "/home/airflow/.local/lib/python3.8/site-packages/airflow/operators/python.py", line 192, in execute
    return_value = self.execute_callable()
  File "/home/airflow/.local/lib/python3.8/site-packages/airflow/operators/python.py", line 209, in execute_callable
    return self.python_callable(*self.op_args, **self.op_kwargs)
  File "/opt/airflow/dags/scripts/extract.py", line 38, in extract_data
    with open("last_update.json", "r") as update_file:
IsADirectoryError: [Errno 21] Is a directory: 'last_update.json'
[2025-04-01T09:24:28.411+0000] {taskinstance.py:1400} INFO - Marking task as UP_FOR_RETRY. dag_id=etl_pipeline, task_id=extract, execution_date=20250401T074500, start_date=20250401T092226, end_date=20250401T092428
[2025-04-01T09:24:28.421+0000] {standard_task_runner.py:104} ERROR - Failed to execute job 200 for task extract ([Errno 21] Is a directory: 'last_update.json'; 71)
[2025-04-01T09:24:28.455+0000] {local_task_job_runner.py:228} INFO - Task exited with return code 1
[2025-04-01T09:24:28.470+0000] {taskinstance.py:2778} INFO - 0 downstream tasks scheduled from follow-on schedule check
