[2025-04-01T09:40:35.488+0000] {taskinstance.py:1159} INFO - Dependencies all met for dep_context=non-requeueable deps ti=<TaskInstance: etl_pipeline.extract scheduled__2025-04-01T07:45:00+00:00 [queued]>
[2025-04-01T09:40:35.493+0000] {taskinstance.py:1159} INFO - Dependencies all met for dep_context=requeueable deps ti=<TaskInstance: etl_pipeline.extract scheduled__2025-04-01T07:45:00+00:00 [queued]>
[2025-04-01T09:40:35.494+0000] {taskinstance.py:1361} INFO - Starting attempt 2 of 2
[2025-04-01T09:40:35.502+0000] {taskinstance.py:1382} INFO - Executing <Task(PythonOperator): extract> on 2025-04-01 07:45:00+00:00
[2025-04-01T09:40:35.507+0000] {standard_task_runner.py:57} INFO - Started process 72 to run task
[2025-04-01T09:40:35.511+0000] {standard_task_runner.py:84} INFO - Running: ['airflow', 'tasks', 'run', 'etl_pipeline', 'extract', 'scheduled__2025-04-01T07:45:00+00:00', '--job-id', '203', '--raw', '--subdir', 'DAGS_FOLDER/etl_dags.py', '--cfg-path', '/tmp/tmpjk_743ll']
[2025-04-01T09:40:35.513+0000] {standard_task_runner.py:85} INFO - Job 203: Subtask extract
[2025-04-01T09:40:35.524+0000] {logging_mixin.py:154} WARNING - /home/airflow/.local/lib/python3.8/site-packages/airflow/settings.py:195 DeprecationWarning: The sql_alchemy_conn option in [core] has been moved to the sql_alchemy_conn option in [database] - the old setting has been used, but please update your config.
[2025-04-01T09:40:35.550+0000] {task_command.py:416} INFO - Running <TaskInstance: etl_pipeline.extract scheduled__2025-04-01T07:45:00+00:00 [running]> on host 486f17ec59cd
[2025-04-01T09:40:35.608+0000] {taskinstance.py:1662} INFO - Exporting env vars: AIRFLOW_CTX_DAG_OWNER='airflow' AIRFLOW_CTX_DAG_ID='etl_pipeline' AIRFLOW_CTX_TASK_ID='extract' AIRFLOW_CTX_EXECUTION_DATE='2025-04-01T07:45:00+00:00' AIRFLOW_CTX_TRY_NUMBER='2' AIRFLOW_CTX_DAG_RUN_ID='scheduled__2025-04-01T07:45:00+00:00'
[2025-04-01T09:42:37.692+0000] {logging_mixin.py:154} INFO - ðŸŒŸ Extract city list completely
[2025-04-01T09:42:37.698+0000] {taskinstance.py:1937} ERROR - Task failed with exception
Traceback (most recent call last):
  File "/home/airflow/.local/lib/python3.8/site-packages/airflow/operators/python.py", line 192, in execute
    return_value = self.execute_callable()
  File "/home/airflow/.local/lib/python3.8/site-packages/airflow/operators/python.py", line 209, in execute_callable
    return self.python_callable(*self.op_args, **self.op_kwargs)
  File "/opt/airflow/dags/scripts/extract.py", line 39, in extract_data
    last_update = json.load(update_file)
  File "/usr/local/lib/python3.8/json/__init__.py", line 293, in load
    return loads(fp.read(),
  File "/usr/local/lib/python3.8/json/__init__.py", line 357, in loads
    return _default_decoder.decode(s)
  File "/usr/local/lib/python3.8/json/decoder.py", line 337, in decode
    obj, end = self.raw_decode(s, idx=_w(s, 0).end())
  File "/usr/local/lib/python3.8/json/decoder.py", line 355, in raw_decode
    raise JSONDecodeError("Expecting value", s, err.value) from None
json.decoder.JSONDecodeError: Expecting value: line 1 column 1 (char 0)
[2025-04-01T09:42:37.712+0000] {taskinstance.py:1400} INFO - Marking task as FAILED. dag_id=etl_pipeline, task_id=extract, execution_date=20250401T074500, start_date=20250401T094035, end_date=20250401T094237
[2025-04-01T09:42:37.724+0000] {standard_task_runner.py:104} ERROR - Failed to execute job 203 for task extract (Expecting value: line 1 column 1 (char 0); 72)
[2025-04-01T09:42:37.737+0000] {local_task_job_runner.py:228} INFO - Task exited with return code 1
[2025-04-01T09:42:37.752+0000] {taskinstance.py:2778} INFO - 0 downstream tasks scheduled from follow-on schedule check
