[2025-03-18T16:45:12.737+0000] {taskinstance.py:1159} INFO - Dependencies all met for dep_context=non-requeueable deps ti=<TaskInstance: etl_pipeline.extract manual__2025-03-18T16:44:16+00:00 [queued]>
[2025-03-18T16:45:12.743+0000] {taskinstance.py:1159} INFO - Dependencies all met for dep_context=requeueable deps ti=<TaskInstance: etl_pipeline.extract manual__2025-03-18T16:44:16+00:00 [queued]>
[2025-03-18T16:45:12.743+0000] {taskinstance.py:1361} INFO - Starting attempt 1 of 2
[2025-03-18T16:45:12.752+0000] {taskinstance.py:1382} INFO - Executing <Task(PythonOperator): extract> on 2025-03-18 16:44:16+00:00
[2025-03-18T16:45:12.756+0000] {standard_task_runner.py:57} INFO - Started process 311 to run task
[2025-03-18T16:45:12.758+0000] {standard_task_runner.py:84} INFO - Running: ['airflow', 'tasks', 'run', 'etl_pipeline', 'extract', 'manual__2025-03-18T16:44:16+00:00', '--job-id', '40', '--raw', '--subdir', 'DAGS_FOLDER/etl_dags.py', '--cfg-path', '/tmp/tmpa4uamdkf']
[2025-03-18T16:45:12.759+0000] {standard_task_runner.py:85} INFO - Job 40: Subtask extract
[2025-03-18T16:45:12.770+0000] {logging_mixin.py:154} WARNING - /home/airflow/.local/lib/python3.8/site-packages/airflow/settings.py:195 DeprecationWarning: The sql_alchemy_conn option in [core] has been moved to the sql_alchemy_conn option in [database] - the old setting has been used, but please update your config.
[2025-03-18T16:45:12.793+0000] {task_command.py:416} INFO - Running <TaskInstance: etl_pipeline.extract manual__2025-03-18T16:44:16+00:00 [running]> on host 792622105a9d
[2025-03-18T16:45:12.840+0000] {taskinstance.py:1662} INFO - Exporting env vars: AIRFLOW_CTX_DAG_OWNER='airflow' AIRFLOW_CTX_DAG_ID='etl_pipeline' AIRFLOW_CTX_TASK_ID='extract' AIRFLOW_CTX_EXECUTION_DATE='2025-03-18T16:44:16+00:00' AIRFLOW_CTX_TRY_NUMBER='1' AIRFLOW_CTX_DAG_RUN_ID='manual__2025-03-18T16:44:16+00:00'
[2025-03-18T16:45:12.844+0000] {taskinstance.py:1937} ERROR - Task failed with exception
Traceback (most recent call last):
  File "/home/airflow/.local/lib/python3.8/site-packages/airflow/operators/python.py", line 192, in execute
    return_value = self.execute_callable()
  File "/home/airflow/.local/lib/python3.8/site-packages/airflow/operators/python.py", line 209, in execute_callable
    return self.python_callable(*self.op_args, **self.op_kwargs)
  File "/opt/airflow/dags/scripts/extract.py", line 14, in extract_data
    with open("./districts.json", "r", encoding="utf-8") as f:
FileNotFoundError: [Errno 2] No such file or directory: './districts.json'
[2025-03-18T16:45:12.852+0000] {taskinstance.py:1400} INFO - Marking task as UP_FOR_RETRY. dag_id=etl_pipeline, task_id=extract, execution_date=20250318T164416, start_date=20250318T164512, end_date=20250318T164512
[2025-03-18T16:45:12.859+0000] {standard_task_runner.py:104} ERROR - Failed to execute job 40 for task extract ([Errno 2] No such file or directory: './districts.json'; 311)
[2025-03-18T16:45:12.892+0000] {local_task_job_runner.py:228} INFO - Task exited with return code 1
[2025-03-18T16:45:12.908+0000] {taskinstance.py:2778} INFO - 0 downstream tasks scheduled from follow-on schedule check
