[2025-03-19T07:41:39.195+0000] {taskinstance.py:1159} INFO - Dependencies all met for dep_context=non-requeueable deps ti=<TaskInstance: etl_pipeline.extract scheduled__2025-03-19T05:00:00+00:00 [queued]>
[2025-03-19T07:41:39.201+0000] {taskinstance.py:1159} INFO - Dependencies all met for dep_context=requeueable deps ti=<TaskInstance: etl_pipeline.extract scheduled__2025-03-19T05:00:00+00:00 [queued]>
[2025-03-19T07:41:39.202+0000] {taskinstance.py:1361} INFO - Starting attempt 3 of 4
[2025-03-19T07:41:39.211+0000] {taskinstance.py:1382} INFO - Executing <Task(PythonOperator): extract> on 2025-03-19 05:00:00+00:00
[2025-03-19T07:41:39.215+0000] {standard_task_runner.py:57} INFO - Started process 322 to run task
[2025-03-19T07:41:39.217+0000] {standard_task_runner.py:84} INFO - Running: ['airflow', 'tasks', 'run', 'etl_pipeline', 'extract', 'scheduled__2025-03-19T05:00:00+00:00', '--job-id', '75', '--raw', '--subdir', 'DAGS_FOLDER/etl_dags.py', '--cfg-path', '/tmp/tmpru6hslps']
[2025-03-19T07:41:39.218+0000] {standard_task_runner.py:85} INFO - Job 75: Subtask extract
[2025-03-19T07:41:39.229+0000] {logging_mixin.py:154} WARNING - /home/airflow/.local/lib/python3.8/site-packages/airflow/settings.py:195 DeprecationWarning: The sql_alchemy_conn option in [core] has been moved to the sql_alchemy_conn option in [database] - the old setting has been used, but please update your config.
[2025-03-19T07:41:39.270+0000] {task_command.py:416} INFO - Running <TaskInstance: etl_pipeline.extract scheduled__2025-03-19T05:00:00+00:00 [running]> on host 9431682cb7a1
[2025-03-19T07:41:39.324+0000] {taskinstance.py:1662} INFO - Exporting env vars: AIRFLOW_CTX_DAG_OWNER='airflow' AIRFLOW_CTX_DAG_ID='etl_pipeline' AIRFLOW_CTX_TASK_ID='extract' AIRFLOW_CTX_EXECUTION_DATE='2025-03-19T05:00:00+00:00' AIRFLOW_CTX_TRY_NUMBER='3' AIRFLOW_CTX_DAG_RUN_ID='scheduled__2025-03-19T05:00:00+00:00'
[2025-03-19T07:41:39.328+0000] {logging_mixin.py:154} INFO - Loading file from: /opt/airflow/dags/scripts/districts.json
[2025-03-19T07:41:55.561+0000] {logging_mixin.py:154} INFO - Saved data for Quan 1
[2025-03-19T07:42:11.739+0000] {logging_mixin.py:154} INFO - Saved data for Quan 2
[2025-03-19T07:42:28.096+0000] {logging_mixin.py:154} INFO - Saved data for Quan 3
[2025-03-19T07:42:44.105+0000] {logging_mixin.py:154} INFO - Saved data for TP Thu Duc
[2025-03-19T07:42:54.556+0000] {local_task_job_runner.py:294} WARNING - State of this instance has been externally set to restarting. Terminating instance.
[2025-03-19T07:42:54.557+0000] {process_utils.py:131} INFO - Sending 15 to group 322. PIDs of all processes in the group: [322]
[2025-03-19T07:42:54.558+0000] {process_utils.py:86} INFO - Sending the signal 15 to group 322
[2025-03-19T07:42:54.558+0000] {taskinstance.py:1632} ERROR - Received SIGTERM. Terminating subprocesses.
[2025-03-19T07:42:54.565+0000] {taskinstance.py:1937} ERROR - Task failed with exception
Traceback (most recent call last):
  File "/home/airflow/.local/lib/python3.8/site-packages/airflow/operators/python.py", line 192, in execute
    return_value = self.execute_callable()
  File "/home/airflow/.local/lib/python3.8/site-packages/airflow/operators/python.py", line 209, in execute_callable
    return self.python_callable(*self.op_args, **self.op_kwargs)
  File "/opt/airflow/dags/scripts/extract.py", line 36, in extract_data
    time.sleep(15)
  File "/home/airflow/.local/lib/python3.8/site-packages/airflow/models/taskinstance.py", line 1634, in signal_handler
    raise AirflowException("Task received SIGTERM signal")
airflow.exceptions.AirflowException: Task received SIGTERM signal
[2025-03-19T07:42:54.573+0000] {taskinstance.py:1400} INFO - Marking task as UP_FOR_RETRY. dag_id=etl_pipeline, task_id=extract, execution_date=20250319T050000, start_date=20250319T074139, end_date=20250319T074254
[2025-03-19T07:42:54.581+0000] {standard_task_runner.py:104} ERROR - Failed to execute job 75 for task extract (Task received SIGTERM signal; 322)
[2025-03-19T07:42:54.611+0000] {process_utils.py:79} INFO - Process psutil.Process(pid=322, status='terminated', exitcode=1, started='07:41:38') (322) terminated with exit code 1
